<mujoco>
    <!-- Arm -->
    <geom conaffinity="0" contype="0" fromto="0 0 0 0 0 0.02" name="root" rgba="0.9 0.4 0.6 1" size=".011" type="cylinder"/>
    <body name="body0" childclass="3dofreacher" pos="0 0 .01">
        <geom fromto="0 0 0 0.1 0 0" name="link0" rgba="0.0 0.4 0.6 1" size=".01" type="capsule"/>
        <joint axis="0 0 1" limited="false" name="joint0" pos="0 0 0" type="hinge"/>
        <joint axis="0 1 0" limited="false" name="joint1" pos="0 0 0" type="hinge"/>
        <body name="body1" pos="0.1 0 0">
            <joint axis="0 0 1" limited="true" name="joint2" pos="0 0 0" range="-3.0 3.0" type="hinge"/>
            <geom fromto="0 0 0 0.1 0 0" name="link1" rgba="0.0 0.4 0.6 1" size=".01" type="capsule"/>
            <body name="fingertip" pos="0.11 0 0">
                <geom contype="0" name="fingertip" rgba="0.0 0.8 0.6 1" size=".01" type="sphere"/>
            </body>
        </body>
    </body>
</mujoco>