<?xml version="1.0" encoding="utf-8"?>
<mujoco>
    <compiler angle="radian" inertiafromgeom="true"/>
    <option gravity="0 0 -9.81" integrator="RK4" timestep="0.01"/>

    <include file="shared.xml"/>

    <include file="mocap_statement.xml"/>

    <worldbody>
        <!-- fingertip mocap -->
        <body mocap="true" name="mocap" pos="0.21 0.0 0.01">
            <geom contype="0" conaffinity="0" rgba="1 1 1 1" size=".01" type="sphere"/>
        </body>
        <!-- Arena -->
        <!--<geom conaffinity="0" contype="0" name="ground" pos="0 0 0" rgba="0.9 0.9 0.9 1" size="1 1 10" type="plane"/>-->
        <geom conaffinity="0" fromto="-.3 -.3 .01 .3 -.3 .01" name="sideS" rgba="0.9 0.4 0.6 1" size=".02" type="capsule"/>
        <geom conaffinity="0" fromto=" .3 -.3 .01 .3  .3 .01" name="sideE" rgba="0.9 0.4 0.6 1" size=".02" type="capsule"/>
        <geom conaffinity="0" fromto="-.3  .3 .01 .3  .3 .01" name="sideN" rgba="0.9 0.4 0.6 1" size=".02" type="capsule"/>
        <geom conaffinity="0" fromto="-.3 -.3 .01 -.3 .3 .01" name="sideW" rgba="0.9 0.4 0.6 1" size=".02" type="capsule"/>
        <!-- Arm -->
        <include file="robot.xml"/>
        <!-- Target -->
        <body name="target" pos=".1 -.1 .01">
            <joint armature="0" axis="1 0 0" damping="0" limited="true" name="target_x" pos="0 0 0" range="-.27 .27" ref=".1" stiffness="0" type="slide"/>
            <joint armature="0" axis="0 1 0" damping="0" limited="true" name="target_y" pos="0 0 0" range="-.27 .27" ref="-.1" stiffness="0" type="slide"/>
            <joint armature="0" axis="0 0 1" damping="0" limited="true" name="target_z" pos="0 0 0" range="-.27 .27" ref="-.1" stiffness="0" type="slide"/>
            <geom conaffinity="0" contype="0" name="target" pos="0 0 0" rgba="0.9 0.2 0.2 1" size=".009" type="sphere"/>
        </body>
    </worldbody>

    <actuator>
        <motor ctrllimited="true" ctrlrange="-1.0 1.0" gear="200.0" joint="joint0"/>
        <motor ctrllimited="true" ctrlrange="-1.0 1.0" gear="200.0" joint="joint1"/>
        <motor ctrllimited="true" ctrlrange="-1.0 1.0" gear="200.0" joint="joint2"/>
    </actuator>
</mujoco>
